<mujoco model="ur5e">
  <compiler angle="radian" meshdir="assets" autolimits="true"/>

  <option integrator="implicitfast"/>

  <default>
    <default class="ur5e">
      <material specular="0.5" shininess="0.25"/>
      <joint axis="0 1 0" range="-6.28319 6.28319" armature="0.1"/>
      <general gaintype="fixed" biastype="affine" ctrlrange="-6.2831 6.2831" gainprm="2000" biasprm="0 -2000 -400" forcerange="-150 150"/>
      <default class="size3">
        <default class="size3_limited">
          <joint range="-3.1415 3.1415"/>
          <general ctrlrange="-3.1415 3.1415"/>
        </default>
      </default>
      <default class="size1">
        <general gainprm="500" biasprm="0 -500 -100" forcerange="-28 28"/>
      </default>
      <default class="visual">
        <geom type="mesh" contype="0" conaffinity="0" group="2"/>
      </default>
      <default class="collision">
        <geom type="capsule" group="3"/>
        <default class="eef_collision">
          <geom type="cylinder"/>
        </default>
      </default>
      <site size="0.001" rgba="0.5 0.5 0.5 0.3" group="4"/>
    </default>
    <default class="2f85">
      <mesh scale="0.001 0.001 0.001"/>
      <general biastype="affine"/>
      <site type="sphere" rgba="0.9 0.9 0.9 1" size="0.005" group="4"/>
      <joint axis="1 0 0"/>
      <default class="driver">
        <joint range="0 0.8" armature="0.005" damping="0.1" solimplimit="0.95 0.99 0.001" solreflimit="0.005 1"/>
      </default>
      <default class="follower">
        <joint range="-0.872664 0.872664" pos="0 -0.018 0.0065" solimplimit="0.95 0.99 0.001" solreflimit="0.005 1"/>
      </default>
      <default class="spring_link">
        <joint range="-0.29670597283 0.8" stiffness="0.05" springref="2.62" damping="0.00125"/>
      </default>
      <default class="coupler">
        <joint range="-1.57 0" solimplimit="0.95 0.99 0.001" solreflimit="0.005 1"/>
      </default>
      <default class="af85_visual">
        <geom type="mesh" contype="0" conaffinity="0" group="2"/>
      </default>
      <default class="af85_collision">
        <geom type="mesh" group="3"/>
        <default class="pad_box1">
          <geom mass="0" type="box" pos="0 -0.0026 0.028125" size="0.011 0.004 0.009375" friction="0.7" solimp="0.95 0.99 0.001" solref="0.004 1" priority="1" rgba="0.55 0.55 0.55 1"/>
        </default>
        <default class="pad_box2">
          <geom mass="0" type="box" pos="0 -0.0026 0.009375" size="0.011 0.004 0.009375" friction="0.6" solimp="0.95 0.99 0.001" solref="0.004 1" priority="1" rgba="0.45 0.45 0.45 1"/>
        </default>
      </default>
    </default>
  </default>

  <asset>
    <material class="ur5e" name="black" rgba="0.033 0.033 0.033 1"/>
    <material class="ur5e" name="jointgray" rgba="0.278 0.278 0.278 1"/>
    <material class="ur5e" name="linkgray" rgba="0.82 0.82 0.82 1"/>
    <material class="ur5e" name="urblue" rgba="0.49 0.678 0.8 1"/>
    <material name="white" rgba="1 1 1 1"/>
    <material name="off_white" rgba="0.901961 0.921569 0.929412 1"/>
    <material name="dark_grey" rgba="0.25 0.25 0.25 1"/>
    <material name="green" rgba="0 1 0 1"/>
    <material name="light_blue" rgba="0.039216 0.541176 0.780392 1"/>
    <material name="metal" rgba="0.58 0.58 0.58 1"/>
    <material name="silicone" rgba="0.1882 0.1882 0.1882 1"/>
    <material name="gray" rgba="0.4627 0.4627 0.4627 1"/>
    <material name="af85_black" rgba="0.149 0.149 0.149 1"/>

    <mesh file="base_0.obj"/>
    <mesh file="base_1.obj"/>
    <mesh file="shoulder_0.obj"/>
    <mesh file="shoulder_1.obj"/>
    <mesh file="shoulder_2.obj"/>
    <mesh file="upperarm_0.obj"/>
    <mesh file="upperarm_1.obj"/>
    <mesh file="upperarm_2.obj"/>
    <mesh file="upperarm_3.obj"/>
    <mesh file="forearm_0.obj"/>
    <mesh file="forearm_1.obj"/>
    <mesh file="forearm_2.obj"/>
    <mesh file="forearm_3.obj"/>
    <mesh file="wrist1_0.obj"/>
    <mesh file="wrist1_1.obj"/>
    <mesh file="wrist1_2.obj"/>
    <mesh file="wrist2_0.obj"/>
    <mesh file="wrist2_1.obj"/>
    <mesh file="wrist2_2.obj"/>
    <mesh file="wrist3.obj"/>
    <mesh class="2f85" file="robotiq_af85_assets/base_mount.stl"/>
    <mesh class="2f85" file="robotiq_af85_assets/base.stl"/>
    <mesh class="2f85" file="robotiq_af85_assets/driver.stl"/>
    <mesh class="2f85" file="robotiq_af85_assets/coupler.stl"/>
    <mesh class="2f85" file="robotiq_af85_assets/follower.stl"/>
    <mesh class="2f85" file="robotiq_af85_assets/pad.stl"/>
    <mesh class="2f85" file="robotiq_af85_assets/silicone_pad.stl"/>
    <mesh class="2f85" file="robotiq_af85_assets/spring_link.stl"/>

  </asset>

  <worldbody>
    <light name="spotlight" mode="targetbodycom" target="wrist_2_link" pos="0 -1 2"/>
    <body name="base" quat="1 0 0 1" childclass="ur5e">
      <inertial mass="4.0" pos="0 0 0" diaginertia="0.00443333156 0.00443333156 0.0072"/>
      <geom mesh="base_0" material="black" class="visual"/>
      <geom mesh="base_1" material="jointgray" class="visual"/>
      <body name="shoulder_link" pos="0 0 0.163">
        <inertial mass="3.7" pos="0 0 0" diaginertia="0.0102675 0.0102675 0.00666"/>
        <joint name="shoulder_pan_joint" class="size3" axis="0 0 1"/>
        <geom mesh="shoulder_0" material="urblue" class="visual"/>
        <geom mesh="shoulder_1" material="black" class="visual"/>
        <geom mesh="shoulder_2" material="jointgray" class="visual"/>
        <geom class="collision" size="0.06 0.06" pos="0 0 -0.04"/>
        <body name="upper_arm_link" pos="0 0.138 0" quat="1 0 1 0">
          <inertial mass="8.393" pos="0 0 0.2125" diaginertia="0.133886 0.133886 0.0151074"/>
          <joint name="shoulder_lift_joint" class="size3"/>
          <geom mesh="upperarm_0" material="linkgray" class="visual"/>
          <geom mesh="upperarm_1" material="black" class="visual"/>
          <geom mesh="upperarm_2" material="jointgray" class="visual"/>
          <geom mesh="upperarm_3" material="urblue" class="visual"/>
          <geom class="collision" pos="0 -0.04 0" quat="1 1 0 0" size="0.06 0.06"/>
          <geom class="collision" size="0.05 0.2" pos="0 0 0.2"/>
          <body name="forearm_link" pos="0 -0.131 0.425">
            <inertial mass="2.275" pos="0 0 0.196" diaginertia="0.0311796 0.0311796 0.004095"/>
            <joint name="elbow_joint" class="size3_limited"/>
            <geom mesh="forearm_0" material="urblue" class="visual"/>
            <geom mesh="forearm_1" material="linkgray" class="visual"/>
            <geom mesh="forearm_2" material="black" class="visual"/>
            <geom mesh="forearm_3" material="jointgray" class="visual"/>
            <geom class="collision" pos="0 0.08 0" quat="1 1 0 0" size="0.055 0.06"/>
            <geom class="collision" size="0.038 0.19" pos="0 0 0.2"/>
            <body name="wrist_1_link" pos="0 0 0.392" quat="1 0 1 0">
              <inertial mass="1.219" pos="0 0.127 0" diaginertia="0.0025599 0.0025599 0.0021942"/>
              <joint name="wrist_1_joint" class="size1"/>
              <geom mesh="wrist1_0" material="black" class="visual"/>
              <geom mesh="wrist1_1" material="urblue" class="visual"/>
              <geom mesh="wrist1_2" material="jointgray" class="visual"/>
              <geom class="collision" pos="0 0.05 0" quat="1 1 0 0" size="0.04 0.07"/>
              <body name="wrist_2_link" pos="0 0.127 0">
                <inertial mass="1.219" pos="0 0 0.1" diaginertia="0.0025599 0.0025599 0.0021942"/>
                <joint name="wrist_2_joint" axis="0 0 1" class="size1"/>
                <geom mesh="wrist2_0" material="black" class="visual"/>
                <geom mesh="wrist2_1" material="urblue" class="visual"/>
                <geom mesh="wrist2_2" material="jointgray" class="visual"/>
                <geom class="collision" size="0.04 0.06" pos="0 0 0.04"/>
                <geom class="collision" pos="0 0.02 0.1" quat="1 1 0 0" size="0.04 0.04"/>
                <body name="wrist_3_link" pos="0 0 0.1">
                  <inertial mass="0.1889" pos="0 0.0771683 0" quat="1 0 0 1" diaginertia="0.000132134 9.90863e-05 9.90863e-05"/>
                  <joint name="wrist_3_joint" class="size1"/>
                  <geom material="linkgray" mesh="wrist3" class="visual"/>
                  <geom class="eef_collision" pos="0 0.08 0" quat="1 1 0 0" size="0.04 0.02"/>

                  <body name="tool0_link" pos="0 0.1 0" quat="-1 1 0 0">
                    <site name="attachment_site_2" pos="0 0 0" quat="1 0 0 0"/>
                    <site name="eef_site" pos="0 0 0.05" quat="0 0.7071068 -0.7071068 0"/>
                    <body name="attachment" pos="0 0 0" quat="1 0 0 0">
                      <site name="attachment_site" rgba="1 0 0 1" size="0.01" group="1"/>
                      <body name="base_mount" quat="1 0 0 1" childclass="2f85">
                        <geom class="af85_visual" mesh="base_mount" material="black"/>
                        <geom class="af85_collision" mesh="base_mount"/>
                        <body name="af85_base" pos="0 0 0.0038" quat="1 0 0 -1">
                          <inertial mass="0.777441" pos="0 -2.70394e-05 0.0354675" quat="1 -0.00152849 0 0" diaginertia="0.000260285 0.000225381 0.000152708"/>
                          <geom class="af85_visual" mesh="base" material="black"/>
                          <geom class="af85_collision" mesh="base"/>
                          <site name="pinch" pos="0 0 0.145"/>
                          <body name="right_driver" pos="0 0.0306011 0.054904">
                            <inertial mass="0.00899563" pos="2.96931e-12 0.0177547 0.00107314" quat="0.681301 0.732003 0 0" diaginertia="1.72352e-06 1.60906e-06 3.22006e-07"/>
                            <joint name="right_driver_joint" class="driver"/>
                            <geom class="af85_visual" mesh="driver" material="gray"/>
                            <geom class="af85_collision" mesh="driver"/>
                            <body name="right_coupler" pos="0 0.0315 -0.0041">
                              <inertial mass="0.0140974" pos="0 0.00301209 0.0232175" quat="0.705636 -0.0455904 0.0455904 0.705636" diaginertia="4.16206e-06 3.52216e-06 8.88131e-07"/>
                              <joint name="right_coupler_joint" class="coupler"/>
                              <geom class="af85_visual" mesh="coupler" material="black"/>
                              <geom class="af85_collision" mesh="coupler"/>
                            </body>
                          </body>
                          <body name="right_spring_link" pos="0 0.0132 0.0609">
                            <inertial mass="0.0221642" pos="-8.65005e-09 0.0181624 0.0212658" quat="0.663403 -0.244737 0.244737 0.663403" diaginertia="8.96853e-06 6.71733e-06 2.63931e-06"/>
                            <joint name="right_spring_link_joint" class="spring_link"/>
                            <geom class="af85_visual" mesh="spring_link" material="black"/>
                            <geom class="af85_collision" mesh="spring_link"/>
                            <body name="right_follower" pos="0 0.055 0.0375">
                              <inertial mass="0.0125222" pos="0 -0.011046 0.0124786" quat="1 0.1664 0 0" diaginertia="2.67415e-06 2.4559e-06 6.02031e-07"/>
                              <joint name="right_follower_joint" class="follower"/>
                              <geom class="af85_visual" mesh="follower" material="black"/>
                              <geom class="af85_collision" mesh="follower"/>
                              <body name="right_pad" pos="0 -0.0189 0.01352">
                                <geom class="pad_box1" name="right_pad1"/>
                                <geom class="pad_box2" name="right_pad2"/>
                                <inertial mass="0.0035" pos="0 -0.0025 0.0185" quat="0.707107 0 0 0.707107" diaginertia="4.73958e-07 3.64583e-07 1.23958e-07"/>
                                <geom class="af85_visual" mesh="pad"/>
                                <body name="right_silicone_pad">
                                  <geom class="af85_visual" mesh="silicone_pad" material="black"/>
                                </body>
                              </body>
                            </body>
                          </body>
                          <body name="left_driver" pos="0 -0.0306011 0.054904" quat="0 0 0 1">
                            <inertial mass="0.00899563" pos="0 0.0177547 0.00107314" quat="0.681301 0.732003 0 0" diaginertia="1.72352e-06 1.60906e-06 3.22006e-07"/>
                            <joint name="left_driver_joint" class="driver"/>
                            <geom class="af85_visual" mesh="driver" material="gray"/>
                            <geom class="af85_collision" mesh="driver"/>
                            <body name="left_coupler" pos="0 0.0315 -0.0041">
                              <inertial mass="0.0140974" pos="0 0.00301209 0.0232175" quat="0.705636 -0.0455904 0.0455904 0.705636" diaginertia="4.16206e-06 3.52216e-06 8.88131e-07"/>
                              <joint name="left_coupler_joint" class="coupler"/>
                              <geom class="af85_visual" mesh="coupler" material="black"/>
                              <geom class="af85_collision" mesh="coupler"/>
                            </body>
                          </body>
                          <body name="left_spring_link" pos="0 -0.0132 0.0609" quat="0 0 0 1">
                            <inertial mass="0.0221642" pos="-8.65005e-09 0.0181624 0.0212658" quat="0.663403 -0.244737 0.244737 0.663403" diaginertia="8.96853e-06 6.71733e-06 2.63931e-06"/>
                            <joint name="left_spring_link_joint" class="spring_link"/>
                            <geom class="af85_visual" mesh="spring_link" material="black"/>
                            <geom class="af85_collision" mesh="spring_link"/>
                            <body name="left_follower" pos="0 0.055 0.0375">
                              <inertial mass="0.0125222" pos="0 -0.011046 0.0124786" quat="1 0.1664 0 0" diaginertia="2.67415e-06 2.4559e-06 6.02031e-07"/>
                              <joint name="left_follower_joint" class="follower"/>
                              <geom class="af85_visual" mesh="follower" material="black"/>
                              <geom class="af85_collision" mesh="follower"/>
                              <body name="left_pad" pos="0 -0.0189 0.01352">
                                <geom class="pad_box1" name="left_pad1"/>
                                <geom class="pad_box2" name="left_pad2"/>
                                <inertial mass="0.0035" pos="0 -0.0025 0.0185" quat="1 0 0 1" diaginertia="4.73958e-07 3.64583e-07 1.23958e-07"/>
                                <geom class="af85_visual" mesh="pad"/>
                                <body name="left_silicone_pad">
                                  <geom class="af85_visual" mesh="silicone_pad" material="black"/>
                                </body>
                              </body>
                            </body>
                          </body>
                        </body>
                      </body>
                    </body>
                    <camera name="wrist_camera" pos="0 0 0.11" xyaxes="1 0 0 0 -1 0" fovy="90"/>
                  </body>
                </body>
              </body>
            </body>
          </body>
        </body>
      </body>
    </body>

  </worldbody>

  <actuator>
    <!-- <general class="size3" name="shoulder_pan" joint="shoulder_pan_joint"/>
    <general class="size3" name="shoulder_lift" joint="shoulder_lift_joint"/>
    <general class="size3_limited" name="elbow" joint="elbow_joint"/>
    <general class="size1" name="wrist_1" joint="wrist_1_joint"/>
    <general class="size1" name="wrist_2" joint="wrist_2_joint"/>
    <general class="size1" name="wrist_3" joint="wrist_3_joint"/> -->
  </actuator>
  <contact>
    <exclude body1="base" body2="left_driver"/>
    <exclude body1="base" body2="right_driver"/>
    <exclude body1="base" body2="left_spring_link"/>
    <exclude body1="base" body2="right_spring_link"/>
    <exclude body1="right_coupler" body2="right_follower"/>
    <exclude body1="left_coupler" body2="left_follower"/>
  </contact>

  <!--
    This adds stability to the model by having a tendon that distributes the forces between both
    joints, such that the equality constraint doesn't have to do that much work in order to equalize
    both joints. Since both joints share the same sign, we split the force between both equally by
    setting coef=0.5
  -->
  <tendon>
    <fixed name="split">
      <joint joint="right_driver_joint" coef="0.5"/>
      <joint joint="left_driver_joint" coef="0.5"/>
    </fixed>
  </tendon>

  <equality>
    <connect anchor="0 0 0" body1="right_follower" body2="right_coupler" solimp="0.95 0.99 0.001" solref="0.005 1"/>
    <connect anchor="0 0 0" body1="left_follower" body2="left_coupler" solimp="0.95 0.99 0.001" solref="0.005 1"/>
    <joint joint1="right_driver_joint" joint2="left_driver_joint" polycoef="0 1 0 0 0" solimp="0.95 0.99 0.001"
      solref="0.005 1"/>
  </equality>

  <!--
    The general actuator below is a customized position actuator (with some damping) where
    gainprm[0] != kp (see http://mujoco.org/book/modeling.html#position).
    The reason why gainprm[0] != kp is because the control input range has to be re-scaled to
    [0, 255]. The joint range is currently set at [0, 0.8], the control range is [0, 255] and
    kp = 100. Tau = Kp * scale * control_input - Kp * error, max(Kp * scale * control_input) = 0.8,
    hence scale = 0.8 * 100 / 255
  -->
  <actuator>
    <general class="2f85" name="fingers_actuator" tendon="split" forcerange="-5 5" ctrlrange="0 255"
      gainprm="0.3137255 0 0" biasprm="0 -100 -10"/>
  </actuator>

  <!-- <keyframe>
    <key name="home" qpos="-1.5708 -1.5708 1.5708 -1.5708 -1.5708 0" ctrl="-1.5708 -1.5708 1.5708 -1.5708 -1.5708 0"/> </keyframe> -->
</mujoco>
