<mujoco model="dh_ag95_gripper">
    <compiler angle="radian" meshdir="meshes" autolimits="true"/>

    <option impratio="10"/>

    <default>  
      <joint range="0 0.943"/>
      <general 
        dyntype="none" gaintype="fixed" 
        biastype="affine" dynprm="1 0 0" 
        gainprm="10 0 0" biasprm="0 -10 -0.1"
        forcerange="-5 5" ctrlrange="0 0.943"
      />

      <default class="visual">
        <geom group="2" type="mesh" contype="0" conaffinity="0" density="0"/>
      </default>
      <default class="collision">
        <geom group="3" type="mesh" density="2700"/>

        <default class="pad_box_0">
          <geom friction="1.5 0.1 0.0002" solimp="0.95 0.99 0.001" solref="0.001 1" priority="1" rgba="0.45 0.45 0.45 1"/>
        </default>
        <default class="pad_box_1">
          <geom friction="1.5 0.1 0.0002" solimp="0.95 0.99 0.001" solref="0.001 1" priority="1" rgba="0.55 0.55 0.55 1"/>
        </default>
        
      </default>
    </default>

    <asset>
      <material name="grey" specular="0.5" shininess="0.25" rgba="0.51764705882 0.53764705882 0.54764705882 1"/>
      <material name="black" specular="0.5" shininess="0.25" rgba="0.1 0.1 0.1 1"/>

      <mesh name="base_link" file="base_link.stl" scale="0.001 0.001 0.001"/>
      <mesh name="gripper_body" file="gripper_body.stl" scale="0.001 0.001 0.001"/>
      <mesh name="outer_knuckle" file="outer_knuckle.stl" scale="0.001 0.001 0.001"/>
      <mesh name="inner_knuckle" file="inner_knuckle.stl" scale="0.001 0.001 0.001"/>
      <mesh name="finger" file="finger.stl" scale="0.001 0.001 0.001"/>
      <mesh name="finger_pad_0" file="finger_pad_0.stl" scale="1 1 1"/>
      <mesh name="finger_pad_1" file="finger_pad_1.stl" scale="1 1 1"/>
    </asset>

    <worldbody>
        <body name="base">
          <geom class="collision" mesh="base_link"/>
          <geom class="visual" mesh="base_link" material="grey"/>
          <geom class="collision" mesh="gripper_body"/>
          <geom class="visual" mesh="gripper_body" material="black"/>
        </body>

        <body name="left_inner_knuckle" pos="0.016 -0.0254 0.10586" quat="0.922844 0 0.385173 0">
          <joint name="left_inner_knuckle_joint" pos="0 0 0" axis="0 -1 0"/>

          <geom class="collision" pos="-0.016 0.0254 -0.10586" mesh="inner_knuckle"/>
          <geom class="visual" pos="-0.016 0.0254 -0.10586" mesh="inner_knuckle" material="black"/>

        </body>
        <body name="left_outer_knuckle" pos="0.036673 -0.00875 0.098336" quat="0.924908 0 -0.380191 0">
          <joint name="left_outer_knuckle_joint" pos="0 0 0" axis="0 -1 0"/>

          <geom class="collision" pos="-0.036673 0.00875 -0.098336" mesh="outer_knuckle"/>
          <geom class="visual" pos="-0.036673 0.00875 -0.098336" mesh="outer_knuckle" material="black"/>

          <body name="left_finger" pos="0.055 0 0" quat="0.924908 0 0.380191 0">
            <joint name="left_finger_joint" pos="0 0 0" axis="0 1 0"/>
            
            
            <geom class="collision" pos="-0.091673 0.00875 -0.098336" mesh="finger"/>
            <geom class="visual" pos="-0.091673 0.00875 -0.098336" mesh="finger" material="black"/>

            <geom class="pad_box_0" pos="-0.091673 0.00875 -0.098336" mesh="finger_pad_0"/>
            <geom class="visual" pos="-0.091673 0.00875 -0.098336" mesh="finger_pad_0" material="grey"/>
            <geom class="pad_box_1" pos="-0.091673 0.00875 -0.098336" mesh="finger_pad_1"/>
            <geom class="visual" pos="-0.091673 0.00875 -0.098336" mesh="finger_pad_1" material="grey"/>
          </body>
        </body>
        <body name="right_inner_knuckle" pos="-0.016 0.0254 0.10586" quat="0 0.385173 0 -0.922844">
          <joint name="right_inner_knuckle_joint" pos="0 0 0" axis="0 -1 0"/>

          <geom class="collision" pos="-0.016 0.0254 -0.10586" mesh="inner_knuckle"/>
          <geom class="visual" pos="-0.016 0.0254 -0.10586" mesh="inner_knuckle" material="black"/>
        </body>
        <body name="right_outer_knuckle" pos="-0.036673 0.00875 0.098336" quat="0 0.380191 0 0.924908">
          <joint name="right_outer_knuckle_joint" pos="0 0 0" axis="0 -1 0"/>
          <geom class="collision" pos="-0.036673 0.00875 -0.098336" mesh="outer_knuckle"/>
          <geom class="visual" pos="-0.036673 0.00875 -0.098336" mesh="outer_knuckle" material="black"/>
          
          <body name="right_finger" pos="0.055 0 0" quat="0.924908 0 0.380191 0">
            <joint name="right_finger_joint" pos="0 0 0" axis="0 1 0"/>

            <geom class="collision" pos="-0.091673 0.00875 -0.098336" mesh="finger"/>
            <geom class="visual" pos="-0.091673 0.00875 -0.098336" mesh="finger" material="black"/>

            <geom class="pad_box_0" pos="-0.091673 0.00875 -0.098336" mesh="finger_pad_0"/>
            <geom class="visual" pos="-0.091673 0.00875 -0.098336" mesh="finger_pad_0" material="grey"/>
            <geom class="pad_box_1" pos="-0.091673 0.00875 -0.098336" mesh="finger_pad_1"/>
            <geom class="visual" pos="-0.091673 0.00875 -0.098336" mesh="finger_pad_1" material="grey"/>

          </body>
        </body>
    </worldbody>

    <contact>
      <exclude body1="base" body2="left_inner_knuckle"/>
      <exclude body1="base" body2="left_outer_knuckle"/>
      <exclude body1="base" body2="right_inner_knuckle"/>
      <exclude body1="base" body2="right_outer_knuckle"/>
      <exclude body1="left_inner_knuckle" body2="left_finger"/>
      <exclude body1="right_inner_knuckle" body2="right_finger"/>
    </contact>

    <tendon>
      <fixed name="split">
        <joint joint="left_outer_knuckle_joint" coef="0.5"/>
        <joint joint="right_outer_knuckle_joint" coef="0.5"/>
      </fixed>
    </tendon>

    <equality>
      <connect anchor="-0.020673 0 0.007524" body1="left_finger" body2="left_inner_knuckle" solimp="0.95 0.99 0.001" solref="0.005 1"/>
      <connect anchor="-0.020673 0 0.007524" body1="right_finger" body2="right_inner_knuckle" solimp="0.95 0.99 0.001" solref="0.005 1"/>
      <joint joint1="left_outer_knuckle_joint" joint2="right_outer_knuckle_joint" polycoef="0 1 0 0 0" solimp="0.95 0.99 0.001"
        solref="0.005 1"/>
    </equality>

    <actuator>
      <general name="fingers_actuator" tendon="split"/>
    </actuator>

  </mujoco>
  